Workbook

Sheet Raw Data
A1: Sector | B1: Year | C1: Month | D1: Cereals and products | E1: Meat and fish | F1: Egg | G1: Milk and products | H1: Oils and fats | I1: Fruits | J1: Vegetables | K1: Pulses and products | L1: Sugar and Confectionery | M1: Spices | N1: Non-alcoholic beverages | O1: Prepared meals, snacks, sweets etc. | P1: Food and beverages | Q1: Pan, tobacco and intoxicants | R1: Clothing | S1: Footwear | T1: Clothing and footwear | U1: Housing | V1: Fuel and light | W1: Household goods and services | X1: Health | Y1: Transport and communication | Z1: Recreation and amusement | AA1: Education | AB1: Personal care and effects | AC1: Miscellaneous | AD1: General index
A2: Rural | B2: 2013 | C2: January | D2: 107.5 | E2: 106.3 | F2: 108.1 | G2: 104.9 | H2: 106.1 | I2: 103.9 | J2: 101.9 | K2: 106.1 | L2: 106.8 | M2: 103.1 | N2: 104.8 | O2: 106.7 | P2: 105.5 | Q2: 105.1 | R2: 106.5 | S2: 105.8 | T2: 106.4 | U2: NA | V2: 105.5 | W2: 104.8 | X2: 104 | Y2: 103.3 | Z2: 103.4 | AA2: 103.8 | AB2: 104.7 | AC2: 104 | AD2: 105.1
A3: Urban | B3: 2013 | C3: January | D3: 110.5 | E3: 109.1 | F3: 113 | G3: 103.6 | H3: 103.4 | I3: 102.3 | J3: 102.9 | K3: 105.8 | L3: 105.1 | M3: 101.8 | N3: 105.1 | O3: 107.9 | P3: 105.9 | Q3: 105.2 | R3: 105.9 | S3: 105 | T3: 105.8 | U3: 100.3 | V3: 105.4 | W3: 104.8 | X3: 104.1 | Y3: 103.2 | Z3: 102.9 | AA3: 103.5 | AB3: 104.3 | AC3: 103.7 | AD3: 104
A4: Rural+Urban | B4: 2013 | C4: January | D4: 108.4 | E4: 107.3 | F4: 110 | G4: 104.4 | H4: 105.1 | I4: 103.2 | J4: 102.2 | K4: 106 | L4: 106.2 | M4: 102.7 | N4: 104.9 | O4: 107.3 | P4: 105.6 | Q4: 105.1 | R4: 106.3 | S4: 105.5 | T4: 106.2 | U4: 100.3 | V4: 105.5 | W4: 104.8 | X4: 104 | Y4: 103.2 | Z4: 103.1 | AA4: 103.6 | AB4: 104.5 | AC4: 103.9 | AD4: 104.6
A5: Rural | B5: 2013 | C5: February | D5: 109.2 | E5: 108.7 | F5: 110.2 | G5: 105.4 | H5: 106.7 | I5: 104 | J5: 102.4 | K5: 105.9 | L5: 105.7 | M5: 103.1 | N5: 105.1 | O5: 107.7 | P5: 106.3 | Q5: 105.6 | R5: 107.1 | S5: 106.3 | T5: 107 | U5: NA | V5: 106.2 | W5: 105.2 | X5: 104.4 | Y5: 103.9 | Z5: 104 | AA5: 104.1 | AB5: 104.6 | AC5: 104.4 | AD5: 105.8
A6: Urban | B6: 2013 | C6: February | D6: 112.9 | E6: 112.9 | F6: 116.9 | G6: 104 | H6: 103.5 | I6: 103.1 | J6: 104.9 | K6: 104.1 | L6: 103.8 | M6: 102.3 | N6: 106 | O6: 109 | P6: 107.2 | Q6: 106 | R6: 106.6 | S6: 105.5 | T6: 106.4 | U6: 100.4 | V6: 105.7 | W6: 105.2 | X6: 104.7 | Y6: 104.4 | Z6: 103.3 | AA6: 103.7 | AB6: 104.3 | AC6: 104.3 | AD6: 104.7
A7: Rural+Urban | B7: 2013 | C7: February | D7: 110.4 | E7: 110.2 | F7: 112.8 | G7: 104.9 | H7: 105.5 | I7: 103.6 | J7: 103.2 | K7: 105.3 | L7: 105.1 | M7: 102.8 | N7: 105.5 | O7: 108.3 | P7: 106.6 | Q7: 105.7 | R7: 106.9 | S7: 106 | T7: 106.8 | U7: 100.4 | V7: 106 | W7: 105.2 | X7: 104.5 | Y7: 104.2 | Z7: 103.6 | AA7: 103.9 | AB7: 104.5 | AC7: 104.4 | AD7: 105.3
A8: Rural | B8: 2013 | C8: March | D8: 110.2 | E8: 108.8 | F8: 109.9 | G8: 105.6 | H8: 106.2 | I8: 105.7 | J8: 101.4 | K8: 105.7 | L8: 105 | M8: 103.3 | N8: 105.6 | O8: 108.2 | P8: 106.6 | Q8: 106.5 | R8: 107.6 | S8: 106.8 | T8: 107.5 | U8: NA | V8: 106.1 | W8: 105.6 | X8: 104.7 | Y8: 104.6 | Z8: 104 | AA8: 104.3 | AB8: 104.3 | AC8: 104.6 | AD8: 106
A9: Urban | B9: 2013 | C9: March | D9: 113.9 | E9: 111.4 | F9: 113.2 | G9: 104.3 | H9: 102.7 | I9: 104.9 | J9: 103.8 | K9: 103.5 | L9: 102.6 | M9: 102.4 | N9: 107 | O9: 109.8 | P9: 107.3 | Q9: 106.8 | R9: 107.2 | S9: 106 | T9: 107 | U9: 100.4 | V9: 106 | W9: 105.7 | X9: 105.2 | Y9: 105.5 | Z9: 103.5 | AA9: 103.8 | AB9: 104.2 | AC9: 104.9 | AD9: 105
A10: Rural+Urban | B10: 2013 | C10: March | D10: 111.4 | E10: 109.7 | F10: 111.2 | G10: 105.1 | H10: 104.9 | I10: 105.3 | J10: 102.2 | K10: 105 | L10: 104.2 | M10: 103 | N10: 106.2 | O10: 108.9 | P10: 106.9 | Q10: 106.6 | R10: 107.4 | S10: 106.5 | T10: 107.3 | U10: 100.4 | V10: 106.1 | W10: 105.6 | X10: 104.9 | Y10: 105.1 | Z10: 103.7 | AA10: 104 | AB10: 104.3 | AC10: 104.7 | AD10: 105.5
A11: Rural | B11: 2013 | C11: April | D11: 110.2 | E11: 109.5 | F11: 106.9 | G11: 106.3 | H11: 105.7 | I11: 108.3 | J11: 103.4 | K11: 105.7 | L11: 104.2 | M11: 103.2 | N11: 106.5 | O11: 108.8 | P11: 107.1 | Q11: 107.1 | R11: 108.1 | S11: 107.4 | T11: 108 | U11: NA | V11: 106.5 | W11: 106.1 | X11: 105.1 | Y11: 104.4 | Z11: 104.5 | AA11: 104.8 | AB11: 102.7 | AC11: 104.6 | AD11: 106.4
A12: Urban | B12: 2013 | C12: April | D12: 114.6 | E12: 113.4 | F12: 106 | G12: 104.7 | H12: 102.1 | I12: 109.5 | J12: 109.7 | K12: 104.6 | L12: 102 | M12: 103.5 | N12: 108.2 | O12: 110.6 | P12: 108.8 | Q12: 108.5 | R12: 107.9 | S12: 106.4 | T12: 107.7 | U12: 100.5 | V12: 106.4 | W12: 106.5 | X12: 105.7 | Y12: 105 | Z12: 104 | AA12: 105.2 | AB12: 103.2 | AC12: 105.1 | AD12: 105.7
A13: Rural+Urban | B13: 2013 | C13: April | D13: 111.6 | E13: 110.9 | F13: 106.6 | G13: 105.7 | H13: 104.4 | I13: 108.9 | J13: 105.5 | K13: 105.3 | L13: 103.5 | M13: 103.3 | N13: 107.2 | O13: 109.6 | P13: 107.7 | Q13: 107.5 | R13: 108 | S13: 107 | T13: 107.9 | U13: 100.5 | V13: 106.5 | W13: 106.3 | X13: 105.3 | Y13: 104.7 | Z13: 104.2 | AA13: 105 | AB13: 102.9 | AC13: 104.8 | AD13: 106.1
A14: Rural | B14: 2013 | C14: May | D14: 110.9 | E14: 109.8 | F14: 105.9 | G14: 107.5 | H14: 105.3 | I14: 108.1 | J14: 107.3 | K14: 106.1 | L14: 103.7 | M14: 104 | N14: 107.4 | O14: 109.9 | P14: 108.1 | Q14: 108.1 | R14: 108.8 | S14: 107.9 | T14: 108.6 | U14: NA | V14: 107.5 | W14: 106.8 | X14: 105.7 | Y14: 104.1 | Z14: 105 | AA14: 105.5 | AB14: 102.1 | AC14: 104.8 | AD14: 107.2
A15: Urban | B15: 2013 | C15: May | D15: 115.4 | E15: 114.2 | F15: 102.7 | G15: 105.5 | H15: 101.5 | I15: 110.6 | J15: 123.7 | K15: 105.2 | L15: 101.9 | M15: 105 | N15: 109.1 | O15: 111.3 | P15: 111.1 | Q15: 109.8 | R15: 108.5 | S15: 106.7 | T15: 108.3 | U15: 100.5 | V15: 107.2 | W15: 107.1 | X15: 106.2 | Y15: 103.9 | Z15: 104.6 | AA15: 105.7 | AB15: 102.6 | AC15: 104.9 | AD15: 106.6
A16: Rural+Urban | B16: 2013 | C16: May | D16: 112.3 | E16: 111.3 | F16: 104.7 | G16: 106.8 | H16: 103.9 | I16: 109.3 | J16: 112.9 | K16: 105.8 | L16: 103.1 | M16: 104.3 | N16: 108.1 | O16: 110.5 | P16: 109.2 | Q16: 108.6 | R16: 108.7 | S16: 107.4 | T16: 108.5 | U16: 100.5 | V16: 107.4 | W16: 106.9 | X16: 105.9 | Y16: 104 | Z16: 104.8 | AA16: 105.6 | AB16: 102.3 | AC16: 104.8 | AD16: 106.9
A17: Rural | B17: 2013 | C17: June | D17: 112.3 | E17: 112.1 | F17: 108.1 | G17: 108.3 | H17: 105.9 | I17: 109.2 | J17: 118 | K17: 106.8 | L17: 104.1 | M17: 105.4 | N17: 108.2 | O17: 111 | P17: 110.6 | Q17: 109 | R17: 109.7 | S17: 108.8 | T17: 109.5 | U17: NA | V17: 108.5 | W17: 107.5 | X17: 106.3 | Y17: 105 | Z17: 105.6 | AA17: 106.5 | AB17: 102.5 | AC17: 105.5 | AD17: 108.9
A18: Urban | B18: 2013 | C18: June | D18: 117 | E18: 120.1 | F18: 112.5 | G18: 107.3 | H18: 101.3 | I18: 112.4 | J18: 143.6 | K18: 105.4 | L18: 101.4 | M18: 106.4 | N18: 110 | O18: 112.2 | P18: 115 | Q18: 110.9 | R18: 109.2 | S18: 107.2 | T18: 108.9 | U18: 106.6 | V18: 108 | W18: 107.7 | X18: 106.5 | Y18: 105.2 | Z18: 105.2 | AA18: 108.1 | AB18: 103.3 | AC18: 106.1 | AD18: 109.7
A19: Rural+Urban | B19: 2013 | C19: June | D19: 113.8 | E19: 114.9 | F19: 109.8 | G19: 107.9 | H19: 104.2 | I19: 110.7 | J19: 126.7 | K19: 106.3 | L19: 103.2 | M19: 105.7 | N19: 109 | O19: 111.6 | P19: 112.2 | Q19: 109.5 | R19: 109.5 | S19: 108.1 | T19: 109.3 | U19: 106.6 | V19: 108.3 | W19: 107.6 | X19: 106.4 | Y19: 105.1 | Z19: 105.4 | AA19: 107.4 | AB19: 102.8 | AC19: 105.8 | AD19: 109.3
A20: Rural | B20: 2013 | C20: July | D20: 113.4 | E20: 114.9 | F20: 110.5 | G20: 109.3 | H20: 106.2 | I20: 110.3 | J20: 129.2 | K20: 107.1 | L20: 104.3 | M20: 106.4 | N20: 109.1 | O20: 112.1 | P20: 113.1 | Q20: 109.8 | R20: 110.5 | S20: 109.5 | T20: 110.3 | U20: NA | V20: 109.5 | W20: 108.3 | X20: 106.9 | Y20: 106.8 | Z20: 106.4 | AA20: 107.8 | AB20: 102.5 | AC20: 106.5 | AD20: 110.7
A21: Urban | B21: 2013 | C21: July | D21: 117.8 | E21: 119.2 | F21: 114 | G21: 108.3 | H21: 101.1 | I21: 113.2 | J21: 160.9 | K21: 105.1 | L21: 101.3 | M21: 107.5 | N21: 110.4 | O21: 113.1 | P21: 117.5 | Q21: 111.7 | R21: 109.8 | S21: 107.8 | T21: 109.5 | U21: 107.7 | V21: 108.6 | W21: 108.1 | X21: 107.1 | Y21: 107.3 | Z21: 105.9 | AA21: 110.1 | AB21: 103.2 | AC21: 107.3 | AD21: 111.4
A22: Rural+Urban | B22: 2013 | C22: July | D22: 114.8 | E22: 116.4 | F22: 111.9 | G22: 108.9 | H22: 104.3 | I22: 111.7 | J22: 140 | K22: 106.4 | L22: 103.3 | M22: 106.8 | N22: 109.6 | O22: 112.6 | P22: 114.7 | Q22: 110.3 | R22: 110.2 | S22: 108.8 | T22: 110 | U22: 107.7 | V22: 109.2 | W22: 108.2 | X22: 107 | Y22: 107.1 | Z22: 106.1 | AA22: 109.1 | AB22: 102.8 | AC22: 106.9 | AD22: 111
A23: Rural | B23: 2013 | C23: August | D23: 114.3 | E23: 115.4 | F23: 111.1 | G23: 110 | H23: 106.4 | I23: 110.8 | J23: 138.9 | K23: 107.4 | L23: 104.1 | M23: 106.9 | N23: 109.7 | O23: 112.6 | P23: 114.9 | Q23: 110.7 | R23: 111.3 | S23: 110.2 | T23: 111.1 | U23: NA | V23: 109.9 | W23: 108.7 | X23: 107.5 | Y23: 107.8 | Z23: 106.8 | AA23: 108.7 | AB23: 105 | AC23: 107.5 | AD23: 112.1
A24: Urban | B24: 2013 | C24: August | D24: 118.3 | E24: 120.4 | F24: 112.7 | G24: 108.9 | H24: 101.1 | I24: 108.7 | J24: 177 | K24: 104.7 | L24: 101 | M24: 108.5 | N24: 110.9 | O24: 114.3 | P24: 119.6 | Q24: 112.4 | R24: 110.6 | S24: 108.3 | T24: 110.2 | U24: 108.9 | V24: 109.3 | W24: 108.7 | X24: 107.6 | Y24: 108.1 | Z24: 106.5 | AA24: 110.8 | AB24: 106 | AC24: 108.3 | AD24: 112.7
A25: Rural+Urban | B25: 2013 | C25: August | D25: 115.6 | E25: 117.2 | F25: 111.7 | G25: 109.6 | H25: 104.5 | I25: 109.8 | J25: 151.8 | K25: 106.5 | L25: 103.1 | M25: 107.4 | N25: 110.2 | O25: 113.4 | P25: 116.6 | Q25: 111.2 | R25: 111 | S25: 109.4 | T25: 110.7 | U25: 108.9 | V25: 109.7 | W25: 108.7 | X25: 107.5 | Y25: 108 | Z25: 106.6 | AA25: 109.9 | AB25: 105.4 | AC25: 107.9 | AD25: 112.4
A26: Rural | B26: 2013 | C26: September | D26: 115.4 | E26: 115.7 | F26: 111.7 | G26: 111 | H26: 107.4 | I26: 110.9 | J26: 154 | K26: 108.1 | L26: 104.2 | M26: 107.9 | N26: 110.4 | O26: 114 | P26: 117.8 | Q26: 111.7 | R26: 112.7 | S26: 111.4 | T26: 112.5 | U26: NA | V26: 111.1 | W26: 109.6 | X26: 108.3 | Y26: 109.3 | Z26: 107.7 | AA26: 109.8 | AB26: 106.7 | AC26: 108.7 | AD26: 114.2
A27: Urban | B27: 2013 | C27: September | D27: 118.6 | E27: 119.1 | F27: 113.2 | G27: 109.6 | H27: 101.7 | I27: 103.2 | J27: 174.3 | K27: 105.1 | L27: 100.8 | M27: 109.1 | N27: 111.1 | O27: 115.4 | P27: 119.2 | Q27: 112.9 | R27: 111.4 | S27: 109 | T27: 111.1 | U27: 109.7 | V27: 109.5 | W27: 109.6 | X27: 107.9 | Y27: 110.4 | Z27: 107.4 | AA27: 111.2 | AB27: 106.9 | AC27: 109.4 | AD27: 113.2
A28: Rural+Urban | B28: 2013 | C28: September | D28: 116.4 | E28: 116.9 | F28: 112.3 | G28: 110.5 | H28: 105.3 | I28: 107.3 | J28: 160.9 | K28: 107.1 | L28: 103.1 | M28: 108.3 | N28: 110.7 | O28: 114.6 | P28: 118.3 | Q28: 112 | R28: 112.2 | S28: 110.4 | T28: 111.9 | U28: 109.7 | V28: 110.5 | W28: 109.6 | X28: 108.1 | Y28: 109.9 | Z28: 107.5 | AA28: 110.6 | AB28: 106.8 | AC28: 109 | AD28: 113.7
A29: Rural | B29: 2013 | C29: October | D29: 116.3 | E29: 115.4 | F29: 112.6 | G29: 111.7 | H29: 107.7 | I29: 113.2 | J29: 164.9 | K29: 108.3 | L29: 103.9 | M29: 108.2 | N29: 111.1 | O29: 114.9 | P29: 119.8 | Q29: 112.2 | R29: 113.6 | S29: 112.3 | T29: 113.4 | U29: NA | V29: 111.6 | W29: 110.4 | X29: 108.9 | Y29: 109.3 | Z29: 108.3 | AA29: 110.2 | AB29: 107.5 | AC29: 109.1 | AD29: 115.5
A30: Urban | B30: 2013 | C30: October | D30: 118.9 | E30: 118.1 | F30: 114.5 | G30: 110.4 | H30: 102.3 | I30: 106.2 | J30: 183.5 | K30: 105.3 | L30: 100.2 | M30: 109.6 | N30: 111.4 | O30: 116 | P30: 120.8 | Q30: 113.5 | R30: 112.5 | S30: 109.7 | T30: 112 | U30: 110.5 | V30: 109.7 | W30: 110.2 | X30: 108.2 | Y30: 109.7 | Z30: 108 | AA30: 111.3 | AB30: 107.3 | AC30: 109.4 | AD30: 114
A31: Rural+Urban | B31: 2013 | C31: October | D31: 117.1 | E31: 116.3 | F31: 113.3 | G31: 111.2 | H31: 105.7 | I31: 109.9 | J31: 171.2 | K31: 107.3 | L31: 102.7 | M31: 108.7 | N31: 111.2 | O31: 115.4 | P31: 120.2 | Q31: 112.5 | R31: 113.2 | S31: 111.2 | T31: 112.8 | U31: 110.5 | V31: 110.9 | W31: 110.3 | X31: 108.6 | Y31: 109.5 | Z31: 108.1 | AA31: 110.8 | AB31: 107.4 | AC31: 109.2 | AD31: 114.8
A32: Rural | B32: 2013 | C32: November | D32: 117.3 | E32: 114.9 | F32: 116.2 | G32: 112.8 | H32: 108.9 | I32: 116.6 | J32: 178.1 | K32: 109.1 | L32: 103.6 | M32: 109 | N32: 111.8 | O32: 116 | P32: 122.5 | Q32: 112.8 | R32: 114.6 | S32: 113.1 | T32: 114.4 | U32: NA | V32: 112.6 | W32: 111.3 | X32: 109.7 | Y32: 109.6 | Z32: 108.7 | AA32: 111 | AB32: 108.2 | AC32: 109.8 | AD32: 117.4
A33: Urban | B33: 2013 | C33: November | D33: 119.8 | E33: 116.3 | F33: 122.6 | G33: 112 | H33: 103.2 | I33: 110 | J33: 192.8 | K33: 106.3 | L33: 99.5 | M33: 110.3 | N33: 111.8 | O33: 117.1 | P33: 122.9 | Q33: 114.1 | R33: 113.5 | S33: 110.3 | T33: 113 | U33: 111.1 | V33: 110 | W33: 110.9 | X33: 108.6 | Y33: 109.5 | Z33: 108.5 | AA33: 111.3 | AB33: 107.9 | AC33: 109.6 | AD33: 115
A34: Rural+Urban | B34: 2013 | C34: November | D34: 118.1 | E34: 115.4 | F34: 118.7 | G34: 112.5 | H34: 106.8 | I34: 113.5 | J34: 183.1 | K34: 108.2 | L34: 102.2 | M34: 109.4 | N34: 111.8 | O34: 116.5 | P34: 122.6 | Q34: 113.1 | R34: 114.2 | S34: 111.9 | T34: 113.8 | U34: 111.1 | V34: 111.6 | W34: 111.1 | X34: 109.3 | Y34: 109.5 | Z34: 108.6 | AA34: 111.2 | AB34: 108.1 | AC34: 109.7 | AD34: 116.3
A35: Rural | B35: 2013 | C35: December | D35: 118.4 | E35: 115.9 | F35: 120.4 | G35: 113.8 | H35: 109.5 | I35: 115.5 | J35: 145.7 | K35: 109.5 | L35: 102.9 | M35: 109.8 | N35: 112.1 | O35: 116.8 | P35: 118.7 | Q35: 113.6 | R35: 115.8 | S35: 114 | T35: 115.5 | U35: NA | V35: 112.8 | W35: 112.1 | X35: 110.1 | Y35: 109.9 | Z35: 109.2 | AA35: 111.6 | AB35: 108.1 | AC35: 110.1 | AD35: 115.5
A36: Urban | B36: 2013 | C36: December | D36: 120.5 | E36: 118.1 | F36: 128.5 | G36: 112.8 | H36: 103.4 | I36: 110.7 | J36: 144.8 | K36: 107.1 | L36: 98.6 | M36: 111.9 | N36: 112.1 | O36: 118.1 | P36: 117.8 | Q36: 115 | R36: 114.2 | S36: 110.9 | T36: 113.7 | U36: 110.7 | V36: 110.4 | W36: 111.3 | X36: 109 | Y36: 109.7 | Z36: 108.9 | AA36: 111.4 | AB36: 107.7 | AC36: 109.8 | AD36: 113.3
A37: Rural+Urban | B37: 2013 | C37: December | D37: 119.1 | E37: 116.7 | F37: 123.5 | G37: 113.4 | H37: 107.3 | I37: 113.3 | J37: 145.4 | K37: 108.7 | L37: 101.5 | M37: 110.5 | N37: 112.1 | O37: 117.4 | P37: 118.4 | Q37: 114 | R37: 115.2 | S37: 112.7 | T37: 114.8 | U37: 110.7 | V37: 111.9 | W37: 111.7 | X37: 109.7 | Y37: 109.8 | Z37: 109 | AA37: 111.5 | AB37: 107.9 | AC37: 110 | AD37: 114.5
A38: Rural | B38: 2014 | C38: January | D38: 118.9 | E38: 117.1 | F38: 120.5 | G38: 114.4 | H38: 109 | I38: 115.5 | J38: 123.9 | K38: 109.6 | L38: 101.8 | M38: 110.2 | N38: 112.4 | O38: 117.3 | P38: 116 | Q38: 114 | R38: 116.5 | S38: 114.5 | T38: 116.2 | U38: NA | V38: 113 | W38: 112.6 | X38: 110.6 | Y38: 110.5 | Z38: 109.6 | AA38: 111.8 | AB38: 108.3 | AC38: 110.6 | AD38: 114.2
A39: Urban | B39: 2014 | C39: January | D39: 121.2 | E39: 122 | F39: 129.9 | G39: 113.6 | H39: 102.9 | I39: 112.1 | J39: 118.9 | K39: 107.5 | L39: 96.9 | M39: 112.7 | N39: 112.1 | O39: 119 | P39: 115.5 | Q39: 115.7 | R39: 114.8 | S39: 111.3 | T39: 114.3 | U39: 111.6 | V39: 111 | W39: 111.9 | X39: 109.7 | Y39: 110.8 | Z39: 109.8 | AA39: 111.5 | AB39: 108 | AC39: 110.5 | AD39: 112.9
A40: Rural+Urban | B40: 2014 | C40: January | D40: 119.6 | E40: 118.8 | F40: 124.1 | G40: 114.1 | H40: 106.8 | I40: 113.9 | J40: 122.2 | K40: 108.9 | L40: 100.2 | M40: 111 | N40: 112.3 | O40: 118.1 | P40: 115.8 | Q40: 114.5 | R40: 115.8 | S40: 113.2 | T40: 115.4 | U40: 111.6 | V40: 112.2 | W40: 112.3 | X40: 110.3 | Y40: 110.7 | Z40: 109.7 | AA40: 111.6 | AB40: 108.2 | AC40: 110.6 | AD40: 113.6
...

Sheet Main Data
A1: Sector | B1: Year | C1: Month | D1: Key | E1: Cereals and products | F1: Meat and fish | G1: Egg | H1: Milk and products | I1: Oils and fats | J1: Fruits | K1: Vegetables | L1: Pulses and products | M1: Sugar and Confectionery | N1: Spices | O1: Non-alcoholic beverages | P1: Prepared meals, snacks, sweets etc. | Q1: Food and beverages | R1: Pan, tobacco and intoxicants | S1: Clothing | T1: Footwear | U1: Clothing and footwear | V1: Housing | W1: Fuel and light | X1: Household goods and services | Y1: Health | Z1: Transport and communication | AA1: Recreation and amusement | AB1: Education | AC1: Personal care and effects | AD1: Miscellaneous | AE1: General index
A2: Rural | B2: 2013 | C2: January | D2: =B2&C2&A2 -> 2013JanuaryRural | E2: 107.5 | F2: 106.3 | G2: 108.1 | H2: 104.9 | I2: 106.1 | J2: 103.9 | K2: 101.9 | L2: 106.1 | M2: 106.8 | N2: 103.1 | O2: 104.8 | P2: 106.7 | Q2: 105.5 | R2: 105.1 | S2: 106.5 | T2: 105.8 | U2: 106.4 | V2: NA | W2: 105.5 | X2: 104.8 | Y2: 104 | Z2: 103.3 | AA2: 103.4 | AB2: 103.8 | AC2: 104.7 | AD2: 104 | AE2: 105.1
A3: Urban | B3: 2013 | C3: January | D3: =B3&C3&A3 -> 2013JanuaryUrban | E3: 110.5 | F3: 109.1 | G3: 113 | H3: 103.6 | I3: 103.4 | J3: 102.3 | K3: 102.9 | L3: 105.8 | M3: 105.1 | N3: 101.8 | O3: 105.1 | P3: 107.9 | Q3: 105.9 | R3: 105.2 | S3: 105.9 | T3: 105 | U3: 105.8 | V3: 100.3 | W3: 105.4 | X3: 104.8 | Y3: 104.1 | Z3: 103.2 | AA3: 102.9 | AB3: 103.5 | AC3: 104.3 | AD3: 103.7 | AE3: 104
A4: Rural+Urban | B4: 2013 | C4: January | D4: =B4&C4&A4 -> 2013JanuaryRural+Urban | E4: 108.4 | F4: 107.3 | G4: 110 | H4: 104.4 | I4: 105.1 | J4: 103.2 | K4: 102.2 | L4: 106 | M4: 106.2 | N4: 102.7 | O4: 104.9 | P4: 107.3 | Q4: 105.6 | R4: 105.1 | S4: 106.3 | T4: 105.5 | U4: 106.2 | V4: 100.3 | W4: 105.5 | X4: 104.8 | Y4: 104 | Z4: 103.2 | AA4: 103.1 | AB4: 103.6 | AC4: 104.5 | AD4: 103.9 | AE4: 104.6
A5: Rural | B5: 2013 | C5: February | D5: =B5&C5&A5 -> 2013FebruaryRural | E5: 109.2 | F5: 108.7 | G5: 110.2 | H5: 105.4 | I5: 106.7 | J5: 104 | K5: 102.4 | L5: 105.9 | M5: 105.7 | N5: 103.1 | O5: 105.1 | P5: 107.7 | Q5: 106.3 | R5: 105.6 | S5: 107.1 | T5: 106.3 | U5: 107 | V5: NA | W5: 106.2 | X5: 105.2 | Y5: 104.4 | Z5: 103.9 | AA5: 104 | AB5: 104.1 | AC5: 104.6 | AD5: 104.4 | AE5: 105.8
A6: Urban | B6: 2013 | C6: February | D6: =B6&C6&A6 -> 2013FebruaryUrban | E6: 112.9 | F6: 112.9 | G6: 116.9 | H6: 104 | I6: 103.5 | J6: 103.1 | K6: 104.9 | L6: 104.1 | M6: 103.8 | N6: 102.3 | O6: 106 | P6: 109 | Q6: 107.2 | R6: 106 | S6: 106.6 | T6: 105.5 | U6: 106.4 | V6: 100.4 | W6: 105.7 | X6: 105.2 | Y6: 104.7 | Z6: 104.4 | AA6: 103.3 | AB6: 103.7 | AC6: 104.3 | AD6: 104.3 | AE6: 104.7
A7: Rural+Urban | B7: 2013 | C7: February | D7: =B7&C7&A7 -> 2013FebruaryRural+Urban | E7: 110.4 | F7: 110.2 | G7: 112.8 | H7: 104.9 | I7: 105.5 | J7: 103.6 | K7: 103.2 | L7: 105.3 | M7: 105.1 | N7: 102.8 | O7: 105.5 | P7: 108.3 | Q7: 106.6 | R7: 105.7 | S7: 106.9 | T7: 106 | U7: 106.8 | V7: 100.4 | W7: 106 | X7: 105.2 | Y7: 104.5 | Z7: 104.2 | AA7: 103.6 | AB7: 103.9 | AC7: 104.5 | AD7: 104.4 | AE7: 105.3
A8: Rural | B8: 2013 | C8: March | D8: =B8&C8&A8 -> 2013MarchRural | E8: 110.2 | F8: 108.8 | G8: 109.9 | H8: 105.6 | I8: 106.2 | J8: 105.7 | K8: 101.4 | L8: 105.7 | M8: 105 | N8: 103.3 | O8: 105.6 | P8: 108.2 | Q8: 106.6 | R8: 106.5 | S8: 107.6 | T8: 106.8 | U8: 107.5 | V8: NA | W8: 106.1 | X8: 105.6 | Y8: 104.7 | Z8: 104.6 | AA8: 104 | AB8: 104.3 | AC8: 104.3 | AD8: 104.6 | AE8: 106
A9: Urban | B9: 2013 | C9: March | D9: =B9&C9&A9 -> 2013MarchUrban | E9: 113.9 | F9: 111.4 | G9: 113.2 | H9: 104.3 | I9: 102.7 | J9: 104.9 | K9: 103.8 | L9: 103.5 | M9: 102.6 | N9: 102.4 | O9: 107 | P9: 109.8 | Q9: 107.3 | R9: 106.8 | S9: 107.2 | T9: 106 | U9: 107 | V9: 100.4 | W9: 106 | X9: 105.7 | Y9: 105.2 | Z9: 105.5 | AA9: 103.5 | AB9: 103.8 | AC9: 104.2 | AD9: 104.9 | AE9: 105
A10: Rural+Urban | B10: 2013 | C10: March | D10: =B10&C10&A10 -> 2013MarchRural+Urban | E10: 111.4 | F10: 109.7 | G10: 111.2 | H10: 105.1 | I10: 104.9 | J10: 105.3 | K10: 102.2 | L10: 105 | M10: 104.2 | N10: 103 | O10: 106.2 | P10: 108.9 | Q10: 106.9 | R10: 106.6 | S10: 107.4 | T10: 106.5 | U10: 107.3 | V10: 100.4 | W10: 106.1 | X10: 105.6 | Y10: 104.9 | Z10: 105.1 | AA10: 103.7 | AB10: 104 | AC10: 104.3 | AD10: 104.7 | AE10: 105.5
A11: Rural | B11: 2013 | C11: April | D11: =B11&C11&A11 -> 2013AprilRural | E11: 110.2 | F11: 109.5 | G11: 106.9 | H11: 106.3 | I11: 105.7 | J11: 108.3 | K11: 103.4 | L11: 105.7 | M11: 104.2 | N11: 103.2 | O11: 106.5 | P11: 108.8 | Q11: 107.1 | R11: 107.1 | S11: 108.1 | T11: 107.4 | U11: 108 | V11: NA | W11: 106.5 | X11: 106.1 | Y11: 105.1 | Z11: 104.4 | AA11: 104.5 | AB11: 104.8 | AC11: 102.7 | AD11: 104.6 | AE11: 106.4
A12: Urban | B12: 2013 | C12: April | D12: =B12&C12&A12 -> 2013AprilUrban | E12: 114.6 | F12: 113.4 | G12: 106 | H12: 104.7 | I12: 102.1 | J12: 109.5 | K12: 109.7 | L12: 104.6 | M12: 102 | N12: 103.5 | O12: 108.2 | P12: 110.6 | Q12: 108.8 | R12: 108.5 | S12: 107.9 | T12: 106.4 | U12: 107.7 | V12: 100.5 | W12: 106.4 | X12: 106.5 | Y12: 105.7 | Z12: 105 | AA12: 104 | AB12: 105.2 | AC12: 103.2 | AD12: 105.1 | AE12: 105.7
A13: Rural+Urban | B13: 2013 | C13: April | D13: =B13&C13&A13 -> 2013AprilRural+Urban | E13: 111.6 | F13: 110.9 | G13: 106.6 | H13: 105.7 | I13: 104.4 | J13: 108.9 | K13: 105.5 | L13: 105.3 | M13: 103.5 | N13: 103.3 | O13: 107.2 | P13: 109.6 | Q13: 107.7 | R13: 107.5 | S13: 108 | T13: 107 | U13: 107.9 | V13: 100.5 | W13: 106.5 | X13: 106.3 | Y13: 105.3 | Z13: 104.7 | AA13: 104.2 | AB13: 105 | AC13: 102.9 | AD13: 104.8 | AE13: 106.1
A14: Rural | B14: 2013 | C14: May | D14: =B14&C14&A14 -> 2013MayRural | E14: 110.9 | F14: 109.8 | G14: 105.9 | H14: 107.5 | I14: 105.3 | J14: 108.1 | K14: 107.3 | L14: 106.1 | M14: 103.7 | N14: 104 | O14: 107.4 | P14: 109.9 | Q14: 108.1 | R14: 108.1 | S14: 108.8 | T14: 107.9 | U14: 108.6 | V14: NA | W14: 107.5 | X14: 106.8 | Y14: 105.7 | Z14: 104.1 | AA14: 105 | AB14: 105.5 | AC14: 102.1 | AD14: 104.8 | AE14: 107.2
A15: Urban | B15: 2013 | C15: May | D15: =B15&C15&A15 -> 2013MayUrban | E15: 115.4 | F15: 114.2 | G15: 102.7 | H15: 105.5 | I15: 101.5 | J15: 110.6 | K15: 123.7 | L15: 105.2 | M15: 101.9 | N15: 105 | O15: 109.1 | P15: 111.3 | Q15: 111.1 | R15: 109.8 | S15: 108.5 | T15: 106.7 | U15: 108.3 | V15: 100.5 | W15: 107.2 | X15: 107.1 | Y15: 106.2 | Z15: 103.9 | AA15: 104.6 | AB15: 105.7 | AC15: 102.6 | AD15: 104.9 | AE15: 106.6
A16: Rural+Urban | B16: 2013 | C16: May | D16: =B16&C16&A16 -> 2013MayRural+Urban | E16: 112.3 | F16: 111.3 | G16: 104.7 | H16: 106.8 | I16: 103.9 | J16: 109.3 | K16: 112.9 | L16: 105.8 | M16: 103.1 | N16: 104.3 | O16: 108.1 | P16: 110.5 | Q16: 109.2 | R16: 108.6 | S16: 108.7 | T16: 107.4 | U16: 108.5 | V16: 100.5 | W16: 107.4 | X16: 106.9 | Y16: 105.9 | Z16: 104 | AA16: 104.8 | AB16: 105.6 | AC16: 102.3 | AD16: 104.8 | AE16: 106.9
A17: Rural | B17: 2013 | C17: June | D17: =B17&C17&A17 -> 2013JuneRural | E17: 112.3 | F17: 112.1 | G17: 108.1 | H17: 108.3 | I17: 105.9 | J17: 109.2 | K17: 118 | L17: 106.8 | M17: 104.1 | N17: 105.4 | O17: 108.2 | P17: 111 | Q17: 110.6 | R17: 109 | S17: 109.7 | T17: 108.8 | U17: 109.5 | V17: NA | W17: 108.5 | X17: 107.5 | Y17: 106.3 | Z17: 105 | AA17: 105.6 | AB17: 106.5 | AC17: 102.5 | AD17: 105.5 | AE17: 108.9
A18: Urban | B18: 2013 | C18: June | D18: =B18&C18&A18 -> 2013JuneUrban | E18: 117 | F18: 120.1 | G18: 112.5 | H18: 107.3 | I18: 101.3 | J18: 112.4 | K18: 143.6 | L18: 105.4 | M18: 101.4 | N18: 106.4 | O18: 110 | P18: 112.2 | Q18: 115 | R18: 110.9 | S18: 109.2 | T18: 107.2 | U18: 108.9 | V18: 106.6 | W18: 108 | X18: 107.7 | Y18: 106.5 | Z18: 105.2 | AA18: 105.2 | AB18: 108.1 | AC18: 103.3 | AD18: 106.1 | AE18: 109.7
A19: Rural+Urban | B19: 2013 | C19: June | D19: =B19&C19&A19 -> 2013JuneRural+Urban | E19: 113.8 | F19: 114.9 | G19: 109.8 | H19: 107.9 | I19: 104.2 | J19: 110.7 | K19: 126.7 | L19: 106.3 | M19: 103.2 | N19: 105.7 | O19: 109 | P19: 111.6 | Q19: 112.2 | R19: 109.5 | S19: 109.5 | T19: 108.1 | U19: 109.3 | V19: 106.6 | W19: 108.3 | X19: 107.6 | Y19: 106.4 | Z19: 105.1 | AA19: 105.4 | AB19: 107.4 | AC19: 102.8 | AD19: 105.8 | AE19: 109.3
A20: Rural | B20: 2013 | C20: July | D20: =B20&C20&A20 -> 2013JulyRural | E20: 113.4 | F20: 114.9 | G20: 110.5 | H20: 109.3 | I20: 106.2 | J20: 110.3 | K20: 129.2 | L20: 107.1 | M20: 104.3 | N20: 106.4 | O20: 109.1 | P20: 112.1 | Q20: 113.1 | R20: 109.8 | S20: 110.5 | T20: 109.5 | U20: 110.3 | V20: NA | W20: 109.5 | X20: 108.3 | Y20: 106.9 | Z20: 106.8 | AA20: 106.4 | AB20: 107.8 | AC20: 102.5 | AD20: 106.5 | AE20: 110.7
A21: Urban | B21: 2013 | C21: July | D21: =B21&C21&A21 -> 2013JulyUrban | E21: 117.8 | F21: 119.2 | G21: 114 | H21: 108.3 | I21: 101.1 | J21: 113.2 | K21: 160.9 | L21: 105.1 | M21: 101.3 | N21: 107.5 | O21: 110.4 | P21: 113.1 | Q21: 117.5 | R21: 111.7 | S21: 109.8 | T21: 107.8 | U21: 109.5 | V21: 107.7 | W21: 108.6 | X21: 108.1 | Y21: 107.1 | Z21: 107.3 | AA21: 105.9 | AB21: 110.1 | AC21: 103.2 | AD21: 107.3 | AE21: 111.4
A22: Rural+Urban | B22: 2013 | C22: July | D22: =B22&C22&A22 -> 2013JulyRural+Urban | E22: 114.8 | F22: 116.4 | G22: 111.9 | H22: 108.9 | I22: 104.3 | J22: 111.7 | K22: 140 | L22: 106.4 | M22: 103.3 | N22: 106.8 | O22: 109.6 | P22: 112.6 | Q22: 114.7 | R22: 110.3 | S22: 110.2 | T22: 108.8 | U22: 110 | V22: 107.7 | W22: 109.2 | X22: 108.2 | Y22: 107 | Z22: 107.1 | AA22: 106.1 | AB22: 109.1 | AC22: 102.8 | AD22: 106.9 | AE22: 111
A23: Rural | B23: 2013 | C23: August | D23: =B23&C23&A23 -> 2013AugustRural | E23: 114.3 | F23: 115.4 | G23: 111.1 | H23: 110 | I23: 106.4 | J23: 110.8 | K23: 138.9 | L23: 107.4 | M23: 104.1 | N23: 106.9 | O23: 109.7 | P23: 112.6 | Q23: 114.9 | R23: 110.7 | S23: 111.3 | T23: 110.2 | U23: 111.1 | V23: NA | W23: 109.9 | X23: 108.7 | Y23: 107.5 | Z23: 107.8 | AA23: 106.8 | AB23: 108.7 | AC23: 105 | AD23: 107.5 | AE23: 112.1
A24: Urban | B24: 2013 | C24: August | D24: =B24&C24&A24 -> 2013AugustUrban | E24: 118.3 | F24: 120.4 | G24: 112.7 | H24: 108.9 | I24: 101.1 | J24: 108.7 | K24: 177 | L24: 104.7 | M24: 101 | N24: 108.5 | O24: 110.9 | P24: 114.3 | Q24: 119.6 | R24: 112.4 | S24: 110.6 | T24: 108.3 | U24: 110.2 | V24: 108.9 | W24: 109.3 | X24: 108.7 | Y24: 107.6 | Z24: 108.1 | AA24: 106.5 | AB24: 110.8 | AC24: 106 | AD24: 108.3 | AE24: 112.7
A25: Rural+Urban | B25: 2013 | C25: August | D25: =B25&C25&A25 -> 2013AugustRural+Urban | E25: 115.6 | F25: 117.2 | G25: 111.7 | H25: 109.6 | I25: 104.5 | J25: 109.8 | K25: 151.8 | L25: 106.5 | M25: 103.1 | N25: 107.4 | O25: 110.2 | P25: 113.4 | Q25: 116.6 | R25: 111.2 | S25: 111 | T25: 109.4 | U25: 110.7 | V25: 108.9 | W25: 109.7 | X25: 108.7 | Y25: 107.5 | Z25: 108 | AA25: 106.6 | AB25: 109.9 | AC25: 105.4 | AD25: 107.9 | AE25: 112.4
A26: Rural | B26: 2013 | C26: September | D26: =B26&C26&A26 -> 2013SeptemberRural | E26: 115.4 | F26: 115.7 | G26: 111.7 | H26: 111 | I26: 107.4 | J26: 110.9 | K26: 154 | L26: 108.1 | M26: 104.2 | N26: 107.9 | O26: 110.4 | P26: 114 | Q26: 117.8 | R26: 111.7 | S26: 112.7 | T26: 111.4 | U26: 112.5 | V26: NA | W26: 111.1 | X26: 109.6 | Y26: 108.3 | Z26: 109.3 | AA26: 107.7 | AB26: 109.8 | AC26: 106.7 | AD26: 108.7 | AE26: 114.2
A27: Urban | B27: 2013 | C27: September | D27: =B27&C27&A27 -> 2013SeptemberUrban | E27: 118.6 | F27: 119.1 | G27: 113.2 | H27: 109.6 | I27: 101.7 | J27: 103.2 | K27: 174.3 | L27: 105.1 | M27: 100.8 | N27: 109.1 | O27: 111.1 | P27: 115.4 | Q27: 119.2 | R27: 112.9 | S27: 111.4 | T27: 109 | U27: 111.1 | V27: 109.7 | W27: 109.5 | X27: 109.6 | Y27: 107.9 | Z27: 110.4 | AA27: 107.4 | AB27: 111.2 | AC27: 106.9 | AD27: 109.4 | AE27: 113.2
A28: Rural+Urban | B28: 2013 | C28: September | D28: =B28&C28&A28 -> 2013SeptemberRural+Urban | E28: 116.4 | F28: 116.9 | G28: 112.3 | H28: 110.5 | I28: 105.3 | J28: 107.3 | K28: 160.9 | L28: 107.1 | M28: 103.1 | N28: 108.3 | O28: 110.7 | P28: 114.6 | Q28: 118.3 | R28: 112 | S28: 112.2 | T28: 110.4 | U28: 111.9 | V28: 109.7 | W28: 110.5 | X28: 109.6 | Y28: 108.1 | Z28: 109.9 | AA28: 107.5 | AB28: 110.6 | AC28: 106.8 | AD28: 109 | AE28: 113.7
A29: Rural | B29: 2013 | C29: October | D29: =B29&C29&A29 -> 2013OctoberRural | E29: 116.3 | F29: 115.4 | G29: 112.6 | H29: 111.7 | I29: 107.7 | J29: 113.2 | K29: 164.9 | L29: 108.3 | M29: 103.9 | N29: 108.2 | O29: 111.1 | P29: 114.9 | Q29: 119.8 | R29: 112.2 | S29: 113.6 | T29: 112.3 | U29: 113.4 | V29: NA | W29: 111.6 | X29: 110.4 | Y29: 108.9 | Z29: 109.3 | AA29: 108.3 | AB29: 110.2 | AC29: 107.5 | AD29: 109.1 | AE29: 115.5
A30: Urban | B30: 2013 | C30: October | D30: =B30&C30&A30 -> 2013OctoberUrban | E30: 118.9 | F30: 118.1 | G30: 114.5 | H30: 110.4 | I30: 102.3 | J30: 106.2 | K30: 183.5 | L30: 105.3 | M30: 100.2 | N30: 109.6 | O30: 111.4 | P30: 116 | Q30: 120.8 | R30: 113.5 | S30: 112.5 | T30: 109.7 | U30: 112 | V30: 110.5 | W30: 109.7 | X30: 110.2 | Y30: 108.2 | Z30: 109.7 | AA30: 108 | AB30: 111.3 | AC30: 107.3 | AD30: 109.4 | AE30: 114
A31: Rural+Urban | B31: 2013 | C31: October | D31: =B31&C31&A31 -> 2013OctoberRural+Urban | E31: 117.1 | F31: 116.3 | G31: 113.3 | H31: 111.2 | I31: 105.7 | J31: 109.9 | K31: 171.2 | L31: 107.3 | M31: 102.7 | N31: 108.7 | O31: 111.2 | P31: 115.4 | Q31: 120.2 | R31: 112.5 | S31: 113.2 | T31: 111.2 | U31: 112.8 | V31: 110.5 | W31: 110.9 | X31: 110.3 | Y31: 108.6 | Z31: 109.5 | AA31: 108.1 | AB31: 110.8 | AC31: 107.4 | AD31: 109.2 | AE31: 114.8
A32: Rural | B32: 2013 | C32: November | D32: =B32&C32&A32 -> 2013November Rural | E32: 117.3 | F32: 114.9 | G32: 116.2 | H32: 112.8 | I32: 108.9 | J32: 116.6 | K32: 178.1 | L32: 109.1 | M32: 103.6 | N32: 109 | O32: 111.8 | P32: 116 | Q32: 122.5 | R32: 112.8 | S32: 114.6 | T32: 113.1 | U32: 114.4 | V32: NA | W32: 112.6 | X32: 111.3 | Y32: 109.7 | Z32: 109.6 | AA32: 108.7 | AB32: 111 | AC32: 108.2 | AD32: 109.8 | AE32: 117.4
A33: Urban | B33: 2013 | C33: November | D33: =B33&C33&A33 -> 2013NovemberUrban | E33: 119.8 | F33: 116.3 | G33: 122.6 | H33: 112 | I33: 103.2 | J33: 110 | K33: 192.8 | L33: 106.3 | M33: 99.5 | N33: 110.3 | O33: 111.8 | P33: 117.1 | Q33: 122.9 | R33: 114.1 | S33: 113.5 | T33: 110.3 | U33: 113 | V33: 111.1 | W33: 110 | X33: 110.9 | Y33: 108.6 | Z33: 109.5 | AA33: 108.5 | AB33: 111.3 | AC33: 107.9 | AD33: 109.6 | AE33: 115
A34: Rural+Urban | B34: 2013 | C34: November | D34: =B34&C34&A34 -> 2013NovemberRural+Urban | E34: 118.1 | F34: 115.4 | G34: 118.7 | H34: 112.5 | I34: 106.8 | J34: 113.5 | K34: 183.1 | L34: 108.2 | M34: 102.2 | N34: 109.4 | O34: 111.8 | P34: 116.5 | Q34: 122.6 | R34: 113.1 | S34: 114.2 | T34: 111.9 | U34: 113.8 | V34: 111.1 | W34: 111.6 | X34: 111.1 | Y34: 109.3 | Z34: 109.5 | AA34: 108.6 | AB34: 111.2 | AC34: 108.1 | AD34: 109.7 | AE34: 116.3
A35: Rural | B35: 2013 | C35: December | D35: =B35&C35&A35 -> 2013DecemberRural | E35: 118.4 | F35: 115.9 | G35: 120.4 | H35: 113.8 | I35: 109.5 | J35: 115.5 | K35: 145.7 | L35: 109.5 | M35: 102.9 | N35: 109.8 | O35: 112.1 | P35: 116.8 | Q35: 118.7 | R35: 113.6 | S35: 115.8 | T35: 114 | U35: 115.5 | V35: NA | W35: 112.8 | X35: 112.1 | Y35: 110.1 | Z35: 109.9 | AA35: 109.2 | AB35: 111.6 | AC35: 108.1 | AD35: 110.1 | AE35: 115.5
A36: Urban | B36: 2013 | C36: December | D36: =B36&C36&A36 -> 2013DecemberUrban | E36: 120.5 | F36: 118.1 | G36: 128.5 | H36: 112.8 | I36: 103.4 | J36: 110.7 | K36: 144.8 | L36: 107.1 | M36: 98.6 | N36: 111.9 | O36: 112.1 | P36: 118.1 | Q36: 117.8 | R36: 115 | S36: 114.2 | T36: 110.9 | U36: 113.7 | V36: 110.7 | W36: 110.4 | X36: 111.3 | Y36: 109 | Z36: 109.7 | AA36: 108.9 | AB36: 111.4 | AC36: 107.7 | AD36: 109.8 | AE36: 113.3
A37: Rural+Urban | B37: 2013 | C37: December | D37: =B37&C37&A37 -> 2013DecemberRural+Urban | E37: 119.1 | F37: 116.7 | G37: 123.5 | H37: 113.4 | I37: 107.3 | J37: 113.3 | K37: 145.4 | L37: 108.7 | M37: 101.5 | N37: 110.5 | O37: 112.1 | P37: 117.4 | Q37: 118.4 | R37: 114 | S37: 115.2 | T37: 112.7 | U37: 114.8 | V37: 110.7 | W37: 111.9 | X37: 111.7 | Y37: 109.7 | Z37: 109.8 | AA37: 109 | AB37: 111.5 | AC37: 107.9 | AD37: 110 | AE37: 114.5
A38: Rural | B38: 2014 | C38: January | D38: =B38&C38&A38 -> 2014JanuaryRural | E38: 118.9 | F38: 117.1 | G38: 120.5 | H38: 114.4 | I38: 109 | J38: 115.5 | K38: 123.9 | L38: 109.6 | M38: 101.8 | N38: 110.2 | O38: 112.4 | P38: 117.3 | Q38: 116 | R38: 114 | S38: 116.5 | T38: 114.5 | U38: 116.2 | V38: NA | W38: 113 | X38: 112.6 | Y38: 110.6 | Z38: 110.5 | AA38: 109.6 | AB38: 111.8 | AC38: 108.3 | AD38: 110.6 | AE38: 114.2
A39: Urban | B39: 2014 | C39: January | D39: =B39&C39&A39 -> 2014JanuaryUrban | E39: 121.2 | F39: 122 | G39: 129.9 | H39: 113.6 | I39: 102.9 | J39: 112.1 | K39: 118.9 | L39: 107.5 | M39: 96.9 | N39: 112.7 | O39: 112.1 | P39: 119 | Q39: 115.5 | R39: 115.7 | S39: 114.8 | T39: 111.3 | U39: 114.3 | V39: 111.6 | W39: 111 | X39: 111.9 | Y39: 109.7 | Z39: 110.8 | AA39: 109.8 | AB39: 111.5 | AC39: 108 | AD39: 110.5 | AE39: 112.9
A40: Rural+Urban | B40: 2014 | C40: January | D40: =B40&C40&A40 -> 2014JanuaryRural+Urban | E40: 119.6 | F40: 118.8 | G40: 124.1 | H40: 114.1 | I40: 106.8 | J40: 113.9 | K40: 122.2 | L40: 108.9 | M40: 100.2 | N40: 111 | O40: 112.3 | P40: 118.1 | Q40: 115.8 | R40: 114.5 | S40: 115.8 | T40: 113.2 | U40: 115.4 | V40: 111.6 | W40: 112.2 | X40: 112.3 | Y40: 110.3 | Z40: 110.7 | AA40: 109.7 | AB40: 111.6 | AC40: 108.2 | AD40: 110.6 | AE40: 113.6
...

Sheet Question 1
I1: Coloum | J1: Rural | K1: Urban | L1: Rural+Urban | M1: New Category | O1: New Category Group | P1: Rural | Q1: Urban | R1: Both | S1: Rural (%) | T1: Urban (%) | U1: Both (%)
I2: Cereals and products | J2: 173.2 | K2: 174.7 | L2: 173.7 | M2: Food | O2: Food | P2: =SUMIFS(J:J,$M:$M,$O2) -> 2290.7 | Q2: =SUMIFS(K:K,$M:$M,$O2) -> 2335.1 | R2: =SUMIFS(L:L,$M:$M,$O2) -> 2306.9 | S2: =P2/$P$9 -> 0.50918023 | T2: =Q2/$Q$9 -> 0.50315672 | U2: =R2/$R$9 -> 0.49563854
I3: Meat and fish | J3: 211.5 | K3: 219.4 | L3: 214.3 | M3: Food | O3: Luxury | P3: =SUMIFS(J:J,$M:$M,$O3) -> 558.6 | Q3: =SUMIFS(K:K,$M:$M,$O3) -> 559 | R3: =SUMIFS(L:L,$M:$M,$O3) -> 557.4 | S3: =P3/$P$9 -> 0.12416644 | T3: =Q3/$Q$9 -> 0.12045077 | U3: =R3/$R$9 -> 0.11975765
I4: Egg | J4: 171 | K4: 176.7 | L4: 173.2 | M4: Food | O4: Clothing | P4: =SUMIFS(J:J,$M:$M,$O4) -> 569.9 | Q4: =SUMIFS(K:K,$M:$M,$O4) -> 528.7 | R4: =SUMIFS(L:L,$M:$M,$O4) -> 553.2 | S4: =P4/$P$9 -> 0.12667823 | T4: =Q4/$Q$9 -> 0.11392187 | U4: =R4/$R$9 -> 0.11885528
I5: Milk and products | J5: 179.6 | K5: 179.4 | L5: 179.5 | M5: Food | O5: Housing | P5: =SUMIFS(J:J,$M:$M,$O5) -> 179.8 | Q5: =SUMIFS(K:K,$M:$M,$O5) -> 345.7 | R5: =SUMIFS(L:L,$M:$M,$O5) -> 350.8 | S5: =P5/$P$9 -> 0.039966213 | T5: =Q5/$Q$9 -> 0.074489862 | U5: =R5/$R$9 -> 0.075369543
I6: Oils and fats | J6: 173.3 | K6: 164.4 | L6: 170 | M6: Food | O6: Fuel and Light | P6: =SUMIFS(J:J,$M:$M,$O6) -> 182.5 | Q6: =SUMIFS(K:K,$M:$M,$O6) -> 183.4 | R6: =SUMIFS(L:L,$M:$M,$O6) -> 182.8 | S6: =P6/$P$9 -> 0.040566373 | T6: =Q6/$Q$9 -> 0.039518197 | U6: =R6/$R$9 -> 0.039274665
I7: Fruits | J7: 169 | K7: 175.8 | L7: 172.2 | M7: Food | O7: Service | P7: =SUMIFS(J:J,$M:$M,$O7) -> 537.8 | Q7: =SUMIFS(K:K,$M:$M,$O7) -> 517.4 | R7: =SUMIFS(L:L,$M:$M,$O7) -> 527.6 | S7: =P7/$P$9 -> 0.11954299 | T7: =Q7/$Q$9 -> 0.111487 | U7: =R7/$R$9 -> 0.1133551
I8: Vegetables | J8: 148.7 | K8: 185 | L8: 161 | M8: Food | O8: Miscellaneous | P8: =SUMIFS(J:J,$M:$M,$O8) -> 179.5 | Q8: =SUMIFS(K:K,$M:$M,$O8) -> 171.6 | R8: =SUMIFS(L:L,$M:$M,$O8) -> 175.7 | S8: =P8/$P$9 -> 0.039899529 | T8: =Q8/$Q$9 -> 0.036975587 | U8: =R8/$R$9 -> 0.037749227
I9: Pulses and products | J9: 174.9 | K9: 176.9 | L9: 175.6 | M9: Food | O9: Total | P9: =SUM(P2:P8) -> 4498.8 | Q9: =SUM(Q2:Q8) -> 4640.9 | R9: =SUM(R2:R8) -> 4654.4 | S9: =SUM(S2:S8) -> 1 | T9: =SUM(T2:T8) -> 1 | U9: =SUM(U2:U8) -> 1
I10: Sugar and Confectionery | J10: 121.9 | K10: 124.2 | L10: 122.7 | M10: Food
I11: Spices | J11: 221 | K11: 211.9 | L11: 218 | M11: Food
I12: Non-alcoholic beverages | J12: 178.7 | K12: 165.9 | L12: 173.4 | M12: Food
I13: Prepared meals, snacks, sweets etc. | J13: 191.1 | K13: 197.7 | L13: 194.2 | M13: Food
I14: Food and beverages | J14: 176.8 | K14: 183.1 | L14: 179.1 | M14: Food
I15: Pan, tobacco and intoxicants | J15: 199.9 | K15: 204.2 | L15: 201 | M15: Luxury
I16: Clothing | J16: 191.2 | K16: 181.3 | L16: 187.3 | M16: Clothing
I17: Footwear | J17: 187.9 | K17: 168.1 | L17: 179.7 | M17: Clothing
I18: Clothing and footwear | J18: 190.8 | K18: 179.3 | L18: 186.2 | M18: Clothing
I19: Housing | J19: - | K19: 175.6 | L19: 175.6 | M19: Housing
I20: Fuel and light | J20: 182.5 | K20: 183.4 | L20: 182.8 | M20: Fuel and light
I21: Household goods and services | J21: 179.8 | K21: 170.1 | L21: 175.2 | M21: Housing
I22: Health | J22: 187.8 | K22: 182.2 | L22: 185.7 | M22: Service
I23: Transport and communication | J23: 169.7 | K23: 160.4 | L23: 164.8 | M23: Service
I24: Recreation and amusement | J24: 173.8 | K24: 169.2 | L24: 171.2 | M24: Luxury
I25: Education | J25: 180.3 | K25: 174.8 | L25: 177.1 | M25: Service
I26: Personal care and effects | J26: 184.9 | K26: 185.6 | L26: 185.2 | M26: Luxury
I27: Miscellaneous | J27: 179.5 | K27: 171.6 | L27: 175.7 | M27: Miscellaneous
I28: General index | J28: 179.8 | K28: 178.2 | L28: 179.1
B32: On the bases of border categories we can say that the Food Categories has the highly contribution towards CPI Calcution

Sheet Question 2
AG2: Year | AH2: December | AI2: January | AJ2: Inflation | AN2: November | AO2: December | AP2: Inflation Difference | AQ2: Inflation Difference (%)
AG3: 2017 | AH3: =VLOOKUP(AG3&$AH$2&"Rural+Urban",'Main Data'!$D$1:$AE$373,28,0) -> 137.2 | AI3: =VLOOKUP(AG3&$AI$2&"Rural+Urban",'Main Data'!$D$1:$AE$373,28,0) -> 130.3 | AJ3: =(AH3-AI3)/AI3*100 -> 5.295472 | AM3: Cereals and products | AN3: =INDEX('Main Data'!$A$1:$AE$373,MATCH(2019&'Question 2'!AN$2&"Rural+Urban",'Main Data'!$D$1:$D$373,0),MATCH('Question 2'!AM3,'Main Data'!$A$1:$AE$1,0)) -> 142.5 | AO3: =INDEX('Main Data'!$A$1:$AE$373,MATCH(2019&'Question 2'!AO$2&"Rural+Urban",'Main Data'!$D$1:$D$373,0),MATCH('Question 2'!AM3,'Main Data'!$A$1:$AE$1,0)) -> 143.5 | AP3: =AO3-AN3 -> 1 | AQ3: =AP3/AN3*100 -> 0.70175439
AG4: 2018 | AH4: =VLOOKUP(AG4&$AH$2&"Rural+Urban",'Main Data'!$D$1:$AE$373,28,0) -> 140.1 | AI4: =VLOOKUP(AG4&$AI$2&"Rural+Urban",'Main Data'!$D$1:$AE$373,28,0) -> 136.9 | AJ4: =(AH4-AI4)/AI4*100 -> 2.3374726 | AM4: Meat and fish | AN4: =INDEX('Main Data'!$A$1:$AE$373,MATCH(2019&'Question 2'!AN$2&"Rural+Urban",'Main Data'!$D$1:$D$373,0),MATCH('Question 2'!AM4,'Main Data'!$A$1:$AE$1,0)) -> 163.2 | AO4: =INDEX('Main Data'!$A$1:$AE$373,MATCH(2019&'Question 2'!AO$2&"Rural+Urban",'Main Data'!$D$1:$D$373,0),MATCH('Question 2'!AM4,'Main Data'!$A$1:$AE$1,0)) -> 165 | AP4: =AO4-AN4 -> 1.8 | AQ4: =AP4/AN4*100 -> 1.1029412
AG5: 2019 | AH5: =VLOOKUP(AG5&$AH$2&"Rural+Urban",'Main Data'!$D$1:$AE$373,28,0) -> 150.4 | AI5: =VLOOKUP(AG5&$AI$2&"Rural+Urban",'Main Data'!$D$1:$AE$373,28,0) -> 139.6 | AJ5: =(AH5-AI5)/AI5*100 -> 7.7363897 | AM5: Egg | AN5: =INDEX('Main Data'!$A$1:$AE$373,MATCH(2019&'Question 2'!AN$2&"Rural+Urban",'Main Data'!$D$1:$D$373,0),MATCH('Question 2'!AM5,'Main Data'!$A$1:$AE$1,0)) -> 145.6 | AO5: =INDEX('Main Data'!$A$1:$AE$373,MATCH(2019&'Question 2'!AO$2&"Rural+Urban",'Main Data'!$D$1:$D$373,0),MATCH('Question 2'!AM5,'Main Data'!$A$1:$AE$1,0)) -> 151.1 | AP5: =AO5-AN5 -> 5.5 | AQ5: =AP5/AN5*100 -> 3.7774725
AG6: 2020 | AH6: =VLOOKUP(AG6&$AH$2&"Rural+Urban",'Main Data'!$D$1:$AE$373,28,0) -> 158.9 | AI6: =VLOOKUP(AG6&$AI$2&"Rural+Urban",'Main Data'!$D$1:$AE$373,28,0) -> 150.2 | AJ6: =(AH6-AI6)/AI6*100 -> 5.792277 | AM6: Milk and products | AN6: =INDEX('Main Data'!$A$1:$AE$373,MATCH(2019&'Question 2'!AN$2&"Rural+Urban",'Main Data'!$D$1:$D$373,0),MATCH('Question 2'!AM6,'Main Data'!$A$1:$AE$1,0)) -> 146.7 | AO6: =INDEX('Main Data'!$A$1:$AE$373,MATCH(2019&'Question 2'!AO$2&"Rural+Urban",'Main Data'!$D$1:$D$373,0),MATCH('Question 2'!AM6,'Main Data'!$A$1:$AE$1,0)) -> 148.3 | AP6: =AO6-AN6 -> 1.6 | AQ6: =AP6/AN6*100 -> 1.0906612
AG7: 2021 | AH7: =VLOOKUP(AG7&$AH$2&"Rural+Urban",'Main Data'!$D$1:$AE$373,28,0) -> 166.2 | AI7: =VLOOKUP(AG7&$AI$2&"Rural+Urban",'Main Data'!$D$1:$AE$373,28,0) -> 157.3 | AJ7: =(AH7-AI7)/AI7*100 -> 5.6579784 | AM7: Oils and fats | AN7: =INDEX('Main Data'!$A$1:$AE$373,MATCH(2019&'Question 2'!AN$2&"Rural+Urban",'Main Data'!$D$1:$D$373,0),MATCH('Question 2'!AM7,'Main Data'!$A$1:$AE$1,0)) -> 124.3 | AO7: =INDEX('Main Data'!$A$1:$AE$373,MATCH(2019&'Question 2'!AO$2&"Rural+Urban",'Main Data'!$D$1:$D$373,0),MATCH('Question 2'!AM7,'Main Data'!$A$1:$AE$1,0)) -> 125.7 | AP7: =AO7-AN7 -> 1.4 | AQ7: =AP7/AN7*100 -> 1.1263073
AG8: 2022 | AH8: =VLOOKUP(AG8&$AH$2&"Rural+Urban",'Main Data'!$D$1:$AE$373,28,0) -> 175.7 | AI8: =VLOOKUP(AG8&$AI$2&"Rural+Urban",'Main Data'!$D$1:$AE$373,28,0) -> 165.7 | AJ8: =(AH8-AI8)/AI8*100 -> 6.035003 | AM8: Fruits | AN8: =INDEX('Main Data'!$A$1:$AE$373,MATCH(2019&'Question 2'!AN$2&"Rural+Urban",'Main Data'!$D$1:$D$373,0),MATCH('Question 2'!AM8,'Main Data'!$A$1:$AE$1,0)) -> 147.4 | AO8: =INDEX('Main Data'!$A$1:$AE$373,MATCH(2019&'Question 2'!AO$2&"Rural+Urban",'Main Data'!$D$1:$D$373,0),MATCH('Question 2'!AM8,'Main Data'!$A$1:$AE$1,0)) -> 145.7 | AP8: =AO8-AN8 -> -1.7 | AQ8: =AP8/AN8*100 -> -1.1533243
AG9: 2023 | AH9: =VLOOKUP(AG9&$AH$2&"Rural+Urban",'Main Data'!$D$1:$AE$373,28,0) -> #N/A | AI9: =VLOOKUP(AG9&$AI$2&"Rural+Urban",'Main Data'!$D$1:$AE$373,28,0) -> 176.5 | AJ9: - | AM9: Vegetables | AN9: =INDEX('Main Data'!$A$1:$AE$373,MATCH(2019&'Question 2'!AN$2&"Rural+Urban",'Main Data'!$D$1:$D$373,0),MATCH('Question 2'!AM9,'Main Data'!$A$1:$AE$1,0)) -> 199.6 | AO9: =INDEX('Main Data'!$A$1:$AE$373,MATCH(2019&'Question 2'!AO$2&"Rural+Urban",'Main Data'!$D$1:$D$373,0),MATCH('Question 2'!AM9,'Main Data'!$A$1:$AE$1,0)) -> 217 | AP9: =AO9-AN9 -> 17.4 | AQ9: =AP9/AN9*100 -> 8.7174349
AJ10: =SUM(AJ3:AJ8) -> 32.854593 | AM10: Pulses and products | AN10: =INDEX('Main Data'!$A$1:$AE$373,MATCH(2019&'Question 2'!AN$2&"Rural+Urban",'Main Data'!$D$1:$D$373,0),MATCH('Question 2'!AM10,'Main Data'!$A$1:$AE$1,0)) -> 135.7 | AO10: =INDEX('Main Data'!$A$1:$AE$373,MATCH(2019&'Question 2'!AO$2&"Rural+Urban",'Main Data'!$D$1:$D$373,0),MATCH('Question 2'!AM10,'Main Data'!$A$1:$AE$1,0)) -> 138.3 | AP10: =AO10-AN10 -> 2.6 | AQ10: =AP10/AN10*100 -> 1.9159912
AM11: Sugar and Confectionery | AN11: =INDEX('Main Data'!$A$1:$AE$373,MATCH(2019&'Question 2'!AN$2&"Rural+Urban",'Main Data'!$D$1:$D$373,0),MATCH('Question 2'!AM11,'Main Data'!$A$1:$AE$1,0)) -> 114.2 | AO11: =INDEX('Main Data'!$A$1:$AE$373,MATCH(2019&'Question 2'!AO$2&"Rural+Urban",'Main Data'!$D$1:$D$373,0),MATCH('Question 2'!AM11,'Main Data'!$A$1:$AE$1,0)) -> 114 | AP11: =AO11-AN11 -> -0.2 | AQ11: =AP11/AN11*100 -> -0.17513135
AM12: Spices | AN12: =INDEX('Main Data'!$A$1:$AE$373,MATCH(2019&'Question 2'!AN$2&"Rural+Urban",'Main Data'!$D$1:$D$373,0),MATCH('Question 2'!AM12,'Main Data'!$A$1:$AE$1,0)) -> 147 | AO12: =INDEX('Main Data'!$A$1:$AE$373,MATCH(2019&'Question 2'!AO$2&"Rural+Urban",'Main Data'!$D$1:$D$373,0),MATCH('Question 2'!AM12,'Main Data'!$A$1:$AE$1,0)) -> 148.7 | AP12: =AO12-AN12 -> 1.7 | AQ12: =AP12/AN12*100 -> 1.1564626
AG13: On year 2019 Inflation reason on the base of bucket we created in previous Question | AM13: Non-alcoholic beverages | AN13: =INDEX('Main Data'!$A$1:$AE$373,MATCH(2019&'Question 2'!AN$2&"Rural+Urban",'Main Data'!$D$1:$D$373,0),MATCH('Question 2'!AM13,'Main Data'!$A$1:$AE$1,0)) -> 135.3 | AO13: =INDEX('Main Data'!$A$1:$AE$373,MATCH(2019&'Question 2'!AO$2&"Rural+Urban",'Main Data'!$D$1:$D$373,0),MATCH('Question 2'!AM13,'Main Data'!$A$1:$AE$1,0)) -> 135.8 | AP13: =AO13-AN13 -> 0.5 | AQ13: =AP13/AN13*100 -> 0.36954915
AG14: New Category Group | AH14: Inflation | AI14: Inflation Rate | AM14: Prepared meals, snacks, sweets etc. | AN14: =INDEX('Main Data'!$A$1:$AE$373,MATCH(2019&'Question 2'!AN$2&"Rural+Urban",'Main Data'!$D$1:$D$373,0),MATCH('Question 2'!AM14,'Main Data'!$A$1:$AE$1,0)) -> 157.5 | AO14: =INDEX('Main Data'!$A$1:$AE$373,MATCH(2019&'Question 2'!AO$2&"Rural+Urban",'Main Data'!$D$1:$D$373,0),MATCH('Question 2'!AM14,'Main Data'!$A$1:$AE$1,0)) -> 158 | AP14: =AO14-AN14 -> 0.5 | AQ14: =AP14/AN14*100 -> 0.31746032
AG15: January | AH15: =VLOOKUP("2019"&AG15&"Rural+Urban",'Main Data'!$D$1:$AE$373,28,0) -> 139.6 | AM15: Food and beverages | AN15: =INDEX('Main Data'!$A$1:$AE$373,MATCH(2019&'Question 2'!AN$2&"Rural+Urban",'Main Data'!$D$1:$D$373,0),MATCH('Question 2'!AM15,'Main Data'!$A$1:$AE$1,0)) -> 151.9 | AO15: =INDEX('Main Data'!$A$1:$AE$373,MATCH(2019&'Question 2'!AO$2&"Rural+Urban",'Main Data'!$D$1:$D$373,0),MATCH('Question 2'!AM15,'Main Data'!$A$1:$AE$1,0)) -> 155 | AP15: =AO15-AN15 -> 3.1 | AQ15: =AP15/AN15*100 -> 2.0408163
AG16: February | AH16: =VLOOKUP("2019"&AG16&"Rural+Urban",'Main Data'!$D$1:$AE$373,28,0) -> 139.9 | AI16: =(AH16-AH15)/AH15*100 -> 0.21489971 | AM16: Pan, tobacco and intoxicants | AN16: =INDEX('Main Data'!$A$1:$AE$373,MATCH(2019&'Question 2'!AN$2&"Rural+Urban",'Main Data'!$D$1:$D$373,0),MATCH('Question 2'!AM16,'Main Data'!$A$1:$AE$1,0)) -> 167.9 | AO16: =INDEX('Main Data'!$A$1:$AE$373,MATCH(2019&'Question 2'!AO$2&"Rural+Urban",'Main Data'!$D$1:$D$373,0),MATCH('Question 2'!AM16,'Main Data'!$A$1:$AE$1,0)) -> 168.5 | AP16: =AO16-AN16 -> 0.6 | AQ16: =AP16/AN16*100 -> 0.35735557
AG17: March | AH17: =VLOOKUP("2019"&AG17&"Rural+Urban",'Main Data'!$D$1:$AE$373,28,0) -> 140.4 | AI17: =(AH17-AH16)/AH16*100 -> 0.35739814 | AM17: Clothing | AN17: =INDEX('Main Data'!$A$1:$AE$373,MATCH(2019&'Question 2'!AN$2&"Rural+Urban",'Main Data'!$D$1:$D$373,0),MATCH('Question 2'!AM17,'Main Data'!$A$1:$AE$1,0)) -> 149.9 | AO17: =INDEX('Main Data'!$A$1:$AE$373,MATCH(2019&'Question 2'!AO$2&"Rural+Urban",'Main Data'!$D$1:$D$373,0),MATCH('Question 2'!AM17,'Main Data'!$A$1:$AE$1,0)) -> 150.3 | AP17: =AO17-AN17 -> 0.4 | AQ17: =AP17/AN17*100 -> 0.26684456
AG18: May | AH18: =VLOOKUP("2019"&AG18&"Rural+Urban",'Main Data'!$D$1:$AE$373,28,0) -> 142 | AI18: =(AH18-AH17)/AH17*100 -> 1.1396011 | AM18: Footwear | AN18: =INDEX('Main Data'!$A$1:$AE$373,MATCH(2019&'Question 2'!AN$2&"Rural+Urban",'Main Data'!$D$1:$D$373,0),MATCH('Question 2'!AM18,'Main Data'!$A$1:$AE$1,0)) -> 141 | AO18: =INDEX('Main Data'!$A$1:$AE$373,MATCH(2019&'Question 2'!AO$2&"Rural+Urban",'Main Data'!$D$1:$D$373,0),MATCH('Question 2'!AM18,'Main Data'!$A$1:$AE$1,0)) -> 141.3 | AP18: =AO18-AN18 -> 0.3 | AQ18: =AP18/AN18*100 -> 0.21276596
AG19: June | AH19: =VLOOKUP("2019"&AG19&"Rural+Urban",'Main Data'!$D$1:$AE$373,28,0) -> 142.9 | AI19: =(AH19-AH18)/AH18*100 -> 0.63380282 | AM19: Clothing and footwear | AN19: =INDEX('Main Data'!$A$1:$AE$373,MATCH(2019&'Question 2'!AN$2&"Rural+Urban",'Main Data'!$D$1:$D$373,0),MATCH('Question 2'!AM19,'Main Data'!$A$1:$AE$1,0)) -> 148.6 | AO19: =INDEX('Main Data'!$A$1:$AE$373,MATCH(2019&'Question 2'!AO$2&"Rural+Urban",'Main Data'!$D$1:$D$373,0),MATCH('Question 2'!AM19,'Main Data'!$A$1:$AE$1,0)) -> 149 | AP19: =AO19-AN19 -> 0.4 | AQ19: =AP19/AN19*100 -> 0.269179
AG20: July | AH20: =VLOOKUP("2019"&AG20&"Rural+Urban",'Main Data'!$D$1:$AE$373,28,0) -> 144.2 | AI20: =(AH20-AH19)/AH19*100 -> 0.90972708 | AM20: Housing | AN20: =INDEX('Main Data'!$A$1:$AE$373,MATCH(2019&'Question 2'!AN$2&"Rural+Urban",'Main Data'!$D$1:$D$373,0),MATCH('Question 2'!AM20,'Main Data'!$A$1:$AE$1,0)) -> 153.5 | AO20: =INDEX('Main Data'!$A$1:$AE$373,MATCH(2019&'Question 2'!AO$2&"Rural+Urban",'Main Data'!$D$1:$D$373,0),MATCH('Question 2'!AM20,'Main Data'!$A$1:$AE$1,0)) -> 152.8 | AP20: =AO20-AN20 -> -0.7 | AQ20: =AP20/AN20*100 -> -0.45602606
AG21: August | AH21: =VLOOKUP("2019"&AG21&"Rural+Urban",'Main Data'!$D$1:$AE$373,28,0) -> 145 | AI21: =(AH21-AH20)/AH20*100 -> 0.55478502 | AM21: Fuel and light | AN21: =INDEX('Main Data'!$A$1:$AE$373,MATCH(2019&'Question 2'!AN$2&"Rural+Urban",'Main Data'!$D$1:$D$373,0),MATCH('Question 2'!AM21,'Main Data'!$A$1:$AE$1,0)) -> 142.3 | AO21: =INDEX('Main Data'!$A$1:$AE$373,MATCH(2019&'Question 2'!AO$2&"Rural+Urban",'Main Data'!$D$1:$D$373,0),MATCH('Question 2'!AM21,'Main Data'!$A$1:$AE$1,0)) -> 143.7 | AP21: =AO21-AN21 -> 1.4 | AQ21: =AP21/AN21*100 -> 0.98383696
AG22: September | AH22: =VLOOKUP("2019"&AG22&"Rural+Urban",'Main Data'!$D$1:$AE$373,28,0) -> 145.8 | AI22: =(AH22-AH21)/AH21*100 -> 0.55172414 | AM22: Household goods and services | AN22: =INDEX('Main Data'!$A$1:$AE$373,MATCH(2019&'Question 2'!AN$2&"Rural+Urban",'Main Data'!$D$1:$D$373,0),MATCH('Question 2'!AM22,'Main Data'!$A$1:$AE$1,0)) -> 145.3 | AO22: =INDEX('Main Data'!$A$1:$AE$373,MATCH(2019&'Question 2'!AO$2&"Rural+Urban",'Main Data'!$D$1:$D$373,0),MATCH('Question 2'!AM22,'Main Data'!$A$1:$AE$1,0)) -> 145.8 | AP22: =AO22-AN22 -> 0.5 | AQ22: =AP22/AN22*100 -> 0.34411562
AG23: October | AH23: =VLOOKUP("2019"&AG23&"Rural+Urban",'Main Data'!$D$1:$AE$373,28,0) -> 147.2 | AI23: =(AH23-AH22)/AH22*100 -> 0.96021948 | AM23: Health | AN23: =INDEX('Main Data'!$A$1:$AE$373,MATCH(2019&'Question 2'!AN$2&"Rural+Urban",'Main Data'!$D$1:$D$373,0),MATCH('Question 2'!AM23,'Main Data'!$A$1:$AE$1,0)) -> 149.9 | AO23: =INDEX('Main Data'!$A$1:$AE$373,MATCH(2019&'Question 2'!AO$2&"Rural+Urban",'Main Data'!$D$1:$D$373,0),MATCH('Question 2'!AM23,'Main Data'!$A$1:$AE$1,0)) -> 150.4 | AP23: =AO23-AN23 -> 0.5 | AQ23: =AP23/AN23*100 -> 0.3335557
AG24: November | AH24: =VLOOKUP("2019"&AG24&"Rural+Urban",'Main Data'!$D$1:$AE$373,28,0) -> 148.6 | AI24: =(AH24-AH23)/AH23*100 -> 0.95108696 | AM24: Transport and communication | AN24: =INDEX('Main Data'!$A$1:$AE$373,MATCH(2019&'Question 2'!AN$2&"Rural+Urban",'Main Data'!$D$1:$D$373,0),MATCH('Question 2'!AM24,'Main Data'!$A$1:$AE$1,0)) -> 126.6 | AO24: =INDEX('Main Data'!$A$1:$AE$373,MATCH(2019&'Question 2'!AO$2&"Rural+Urban",'Main Data'!$D$1:$D$373,0),MATCH('Question 2'!AM24,'Main Data'!$A$1:$AE$1,0)) -> 129.8 | AP24: =AO24-AN24 -> 3.2 | AQ24: =AP24/AN24*100 -> 2.5276461
AG25: December | AH25: =VLOOKUP("2019"&AG25&"Rural+Urban",'Main Data'!$D$1:$AE$373,28,0) -> 150.4 | AI25: =(AH25-AH24)/AH24*100 -> 1.2113055 | AM25: Recreation and amusement | AN25: =INDEX('Main Data'!$A$1:$AE$373,MATCH(2019&'Question 2'!AN$2&"Rural+Urban",'Main Data'!$D$1:$D$373,0),MATCH('Question 2'!AM25,'Main Data'!$A$1:$AE$1,0)) -> 142.1 | AO25: =INDEX('Main Data'!$A$1:$AE$373,MATCH(2019&'Question 2'!AO$2&"Rural+Urban",'Main Data'!$D$1:$D$373,0),MATCH('Question 2'!AM25,'Main Data'!$A$1:$AE$1,0)) -> 142.3 | AP25: =AO25-AN25 -> 0.2 | AQ25: =AP25/AN25*100 -> 0.14074595
AI26: =SUM(AI16:AI25) -> 7.48455 | AM26: Education | AN26: =INDEX('Main Data'!$A$1:$AE$373,MATCH(2019&'Question 2'!AN$2&"Rural+Urban",'Main Data'!$D$1:$D$373,0),MATCH('Question 2'!AM26,'Main Data'!$A$1:$AE$1,0)) -> 155.5 | AO26: =INDEX('Main Data'!$A$1:$AE$373,MATCH(2019&'Question 2'!AO$2&"Rural+Urban",'Main Data'!$D$1:$D$373,0),MATCH('Question 2'!AM26,'Main Data'!$A$1:$AE$1,0)) -> 155.7 | AP26: =AO26-AN26 -> 0.2 | AQ26: =AP26/AN26*100 -> 0.12861736
AM27: Personal care and effects | AN27: =INDEX('Main Data'!$A$1:$AE$373,MATCH(2019&'Question 2'!AN$2&"Rural+Urban",'Main Data'!$D$1:$D$373,0),MATCH('Question 2'!AM27,'Main Data'!$A$1:$AE$1,0)) -> 140.3 | AO27: =INDEX('Main Data'!$A$1:$AE$373,MATCH(2019&'Question 2'!AO$2&"Rural+Urban",'Main Data'!$D$1:$D$373,0),MATCH('Question 2'!AM27,'Main Data'!$A$1:$AE$1,0)) -> 140.4 | AP27: =AO27-AN27 -> 0.1 | AQ27: =AP27/AN27*100 -> 0.071275837
AM28: Miscellaneous | AN28: =INDEX('Main Data'!$A$1:$AE$373,MATCH(2019&'Question 2'!AN$2&"Rural+Urban",'Main Data'!$D$1:$D$373,0),MATCH('Question 2'!AM28,'Main Data'!$A$1:$AE$1,0)) -> 141.3 | AO28: =INDEX('Main Data'!$A$1:$AE$373,MATCH(2019&'Question 2'!AO$2&"Rural+Urban",'Main Data'!$D$1:$D$373,0),MATCH('Question 2'!AM28,'Main Data'!$A$1:$AE$1,0)) -> 142.5 | AP28: =AO28-AN28 -> 1.2 | AQ28: =AP28/AN28*100 -> 0.8492569
A34: According to this graph in 2019 had higher inflation rate
I35: In 2019 on December had High Inflation Rate

Sheet Question 3
S2: Food Bucket Category | T2: Cereals and products | U2: Meat and fish | V2: Egg | W2: Milk and products | X2: Oils and fats | Y2: Fruits | Z2: Vegetables | AA2: Pulses and products | AB2: Sugar and Confectionery | AC2: Spices | AD2: Non-alcoholic beverages | AE2: Prepared meals, snacks, sweets etc. | AF2: Food | AH2: YOY Inflation | AI2: 44713 | AJ2: 45047 | AK2: Inflation
S3: 2022AprilRural+Urban | T3: =INDEX('Main Data'!$D$1:$AE$373,MATCH('Question 3'!$S3,'Main Data'!$D$1:$D$373,0),MATCH('Question 3'!T$2,'Main Data'!$D$1:$AE$1,0)) -> 152.9 | U3: =INDEX('Main Data'!$D$1:$AE$373,MATCH('Question 3'!$S3,'Main Data'!$D$1:$D$373,0),MATCH('Question 3'!U$2,'Main Data'!$D$1:$AE$1,0)) -> 211.8 | V3: =INDEX('Main Data'!$D$1:$AE$373,MATCH('Question 3'!$S3,'Main Data'!$D$1:$D$373,0),MATCH('Question 3'!V$2,'Main Data'!$D$1:$AE$1,0)) -> 164.5 | W3: =INDEX('Main Data'!$D$1:$AE$373,MATCH('Question 3'!$S3,'Main Data'!$D$1:$D$373,0),MATCH('Question 3'!W$2,'Main Data'!$D$1:$AE$1,0)) -> 163.9 | X3: =INDEX('Main Data'!$D$1:$AE$373,MATCH('Question 3'!$S3,'Main Data'!$D$1:$D$373,0),MATCH('Question 3'!X$2,'Main Data'!$D$1:$AE$1,0)) -> 199.5 | Y3: =INDEX('Main Data'!$D$1:$AE$373,MATCH('Question 3'!$S3,'Main Data'!$D$1:$D$373,0),MATCH('Question 3'!Y$2,'Main Data'!$D$1:$AE$1,0)) -> 172.6 | Z3: =INDEX('Main Data'!$D$1:$AE$373,MATCH('Question 3'!$S3,'Main Data'!$D$1:$D$373,0),MATCH('Question 3'!Z$2,'Main Data'!$D$1:$AE$1,0)) -> 166.2 | AA3: =INDEX('Main Data'!$D$1:$AE$373,MATCH('Question 3'!$S3,'Main Data'!$D$1:$D$373,0),MATCH('Question 3'!AA$2,'Main Data'!$D$1:$AE$1,0)) -> 164.7 | ... AE3: =INDEX('Main Data'!$D$1:$AE$373,MATCH('Question 3'!$S3,'Main Data'!$D$1:$D$373,0),MATCH('Question 3'!AE$2,'Main Data'!$D$1:$AE$1,0)) -> 180.9 | AF3: =SUM(T3:AE3) -> 2043.5 | AH3: Cereals and products | AI3: =INDEX($S$2:$AE$16,MATCH(2022&"June"&"Rural+Urban",$S$2:$S$16,0),MATCH(AH3,$S$2:$AE$2,0)) -> 155 | AJ3: =INDEX($S$2:$AE$16,MATCH(2023&"May"&"Rural+Urban",$S$2:$S$16,0),MATCH(AH3,$S$2:$AE$2,0)) -> 173.7 | AK3: =(AJ3-AI3)/AI3*100 -> 12.064516
L4: Time duration/ Time Frame | M4: June 2022 to may 2023 | S4: 2022MayRural+Urban | T4: =INDEX('Main Data'!$D$1:$AE$373,MATCH('Question 3'!$S4,'Main Data'!$D$1:$D$373,0),MATCH('Question 3'!T$2,'Main Data'!$D$1:$AE$1,0)) -> 154.1 | U4: =INDEX('Main Data'!$D$1:$AE$373,MATCH('Question 3'!$S4,'Main Data'!$D$1:$D$373,0),MATCH('Question 3'!U$2,'Main Data'!$D$1:$AE$1,0)) -> 217 | V4: =INDEX('Main Data'!$D$1:$AE$373,MATCH('Question 3'!$S4,'Main Data'!$D$1:$D$373,0),MATCH('Question 3'!V$2,'Main Data'!$D$1:$AE$1,0)) -> 162.4 | W4: =INDEX('Main Data'!$D$1:$AE$373,MATCH('Question 3'!$S4,'Main Data'!$D$1:$D$373,0),MATCH('Question 3'!W$2,'Main Data'!$D$1:$AE$1,0)) -> 164.9 | X4: =INDEX('Main Data'!$D$1:$AE$373,MATCH('Question 3'!$S4,'Main Data'!$D$1:$D$373,0),MATCH('Question 3'!X$2,'Main Data'!$D$1:$AE$1,0)) -> 202.4 | Y4: =INDEX('Main Data'!$D$1:$AE$373,MATCH('Question 3'!$S4,'Main Data'!$D$1:$D$373,0),MATCH('Question 3'!Y$2,'Main Data'!$D$1:$AE$1,0)) -> 171 | Z4: =INDEX('Main Data'!$D$1:$AE$373,MATCH('Question 3'!$S4,'Main Data'!$D$1:$D$373,0),MATCH('Question 3'!Z$2,'Main Data'!$D$1:$AE$1,0)) -> 174.9 | AA4: =INDEX('Main Data'!$D$1:$AE$373,MATCH('Question 3'!$S4,'Main Data'!$D$1:$D$373,0),MATCH('Question 3'!AA$2,'Main Data'!$D$1:$AE$1,0)) -> 164.7 | ... AE4: =INDEX('Main Data'!$D$1:$AE$373,MATCH('Question 3'!$S4,'Main Data'!$D$1:$D$373,0),MATCH('Question 3'!AE$2,'Main Data'!$D$1:$AE$1,0)) -> 182.5 | AF4: =SUM(T4:AE4) -> 2065.6 | AH4: Meat and fish | AI4: =INDEX($S$2:$AE$16,MATCH(2022&"June"&"Rural+Urban",$S$2:$S$16,0),MATCH(AH4,$S$2:$AE$2,0)) -> 219.4 | AJ4: =INDEX($S$2:$AE$16,MATCH(2023&"May"&"Rural+Urban",$S$2:$S$16,0),MATCH(AH4,$S$2:$AE$2,0)) -> 214.3 | AK4: =(AJ4-AI4)/AI4*100 -> -2.3245214
L5: In Food Bucket | S5: 2022JuneRural+Urban | T5: =INDEX('Main Data'!$D$1:$AE$373,MATCH('Question 3'!$S5,'Main Data'!$D$1:$D$373,0),MATCH('Question 3'!T$2,'Main Data'!$D$1:$AE$1,0)) -> 155 | U5: =INDEX('Main Data'!$D$1:$AE$373,MATCH('Question 3'!$S5,'Main Data'!$D$1:$D$373,0),MATCH('Question 3'!U$2,'Main Data'!$D$1:$AE$1,0)) -> 219.4 | V5: =INDEX('Main Data'!$D$1:$AE$373,MATCH('Question 3'!$S5,'Main Data'!$D$1:$D$373,0),MATCH('Question 3'!V$2,'Main Data'!$D$1:$AE$1,0)) -> 170.8 | W5: =INDEX('Main Data'!$D$1:$AE$373,MATCH('Question 3'!$S5,'Main Data'!$D$1:$D$373,0),MATCH('Question 3'!W$2,'Main Data'!$D$1:$AE$1,0)) -> 165.8 | X5: =INDEX('Main Data'!$D$1:$AE$373,MATCH('Question 3'!$S5,'Main Data'!$D$1:$D$373,0),MATCH('Question 3'!X$2,'Main Data'!$D$1:$AE$1,0)) -> 200.9 | Y5: =INDEX('Main Data'!$D$1:$AE$373,MATCH('Question 3'!$S5,'Main Data'!$D$1:$D$373,0),MATCH('Question 3'!Y$2,'Main Data'!$D$1:$AE$1,0)) -> 169.7 | Z5: =INDEX('Main Data'!$D$1:$AE$373,MATCH('Question 3'!$S5,'Main Data'!$D$1:$D$373,0),MATCH('Question 3'!Z$2,'Main Data'!$D$1:$AE$1,0)) -> 182.3 | AA5: =INDEX('Main Data'!$D$1:$AE$373,MATCH('Question 3'!$S5,'Main Data'!$D$1:$D$373,0),MATCH('Question 3'!AA$2,'Main Data'!$D$1:$AE$1,0)) -> 164.3 | ... AE5: =INDEX('Main Data'!$D$1:$AE$373,MATCH('Question 3'!$S5,'Main Data'!$D$1:$D$373,0),MATCH('Question 3'!AE$2,'Main Data'!$D$1:$AE$1,0)) -> 183.9 | AF5: =SUM(T5:AE5) -> 2087 | AH5: Egg | AI5: =INDEX($S$2:$AE$16,MATCH(2022&"June"&"Rural+Urban",$S$2:$S$16,0),MATCH(AH5,$S$2:$AE$2,0)) -> 170.8 | AJ5: =INDEX($S$2:$AE$16,MATCH(2023&"May"&"Rural+Urban",$S$2:$S$16,0),MATCH(AH5,$S$2:$AE$2,0)) -> 173.2 | AK5: =(AJ5-AI5)/AI5*100 -> 1.4051522
S6: 2022JulyRural+Urban | T6: =INDEX('Main Data'!$D$1:$AE$373,MATCH('Question 3'!$S6,'Main Data'!$D$1:$D$373,0),MATCH('Question 3'!T$2,'Main Data'!$D$1:$AE$1,0)) -> 156.5 | U6: =INDEX('Main Data'!$D$1:$AE$373,MATCH('Question 3'!$S6,'Main Data'!$D$1:$D$373,0),MATCH('Question 3'!U$2,'Main Data'!$D$1:$AE$1,0)) -> 213 | V6: =INDEX('Main Data'!$D$1:$AE$373,MATCH('Question 3'!$S6,'Main Data'!$D$1:$D$373,0),MATCH('Question 3'!V$2,'Main Data'!$D$1:$AE$1,0)) -> 175.2 | W6: =INDEX('Main Data'!$D$1:$AE$373,MATCH('Question 3'!$S6,'Main Data'!$D$1:$D$373,0),MATCH('Question 3'!W$2,'Main Data'!$D$1:$AE$1,0)) -> 166.6 | X6: =INDEX('Main Data'!$D$1:$AE$373,MATCH('Question 3'!$S6,'Main Data'!$D$1:$D$373,0),MATCH('Question 3'!X$2,'Main Data'!$D$1:$AE$1,0)) -> 195.8 | Y6: =INDEX('Main Data'!$D$1:$AE$373,MATCH('Question 3'!$S6,'Main Data'!$D$1:$D$373,0),MATCH('Question 3'!Y$2,'Main Data'!$D$1:$AE$1,0)) -> 174.2 | Z6: =INDEX('Main Data'!$D$1:$AE$373,MATCH('Question 3'!$S6,'Main Data'!$D$1:$D$373,0),MATCH('Question 3'!Z$2,'Main Data'!$D$1:$AE$1,0)) -> 182.1 | AA6: =INDEX('Main Data'!$D$1:$AE$373,MATCH('Question 3'!$S6,'Main Data'!$D$1:$D$373,0),MATCH('Question 3'!AA$2,'Main Data'!$D$1:$AE$1,0)) -> 164.3 | ... AE6: =INDEX('Main Data'!$D$1:$AE$373,MATCH('Question 3'!$S6,'Main Data'!$D$1:$D$373,0),MATCH('Question 3'!AE$2,'Main Data'!$D$1:$AE$1,0)) -> 185.2 | AF6: =SUM(T6:AE6) -> 2091.3 | AH6: Milk and products | AI6: =INDEX($S$2:$AE$16,MATCH(2022&"June"&"Rural+Urban",$S$2:$S$16,0),MATCH(AH6,$S$2:$AE$2,0)) -> 165.8 | AJ6: =INDEX($S$2:$AE$16,MATCH(2023&"May"&"Rural+Urban",$S$2:$S$16,0),MATCH(AH6,$S$2:$AE$2,0)) -> 179.5 | AK6: =(AJ6-AI6)/AI6*100 -> 8.2629674
S7: 2022AugustRural+Urban | T7: =INDEX('Main Data'!$D$1:$AE$373,MATCH('Question 3'!$S7,'Main Data'!$D$1:$D$373,0),MATCH('Question 3'!T$2,'Main Data'!$D$1:$AE$1,0)) -> 160.3 | U7: =INDEX('Main Data'!$D$1:$AE$373,MATCH('Question 3'!$S7,'Main Data'!$D$1:$D$373,0),MATCH('Question 3'!U$2,'Main Data'!$D$1:$AE$1,0)) -> 206.5 | V7: =INDEX('Main Data'!$D$1:$AE$373,MATCH('Question 3'!$S7,'Main Data'!$D$1:$D$373,0),MATCH('Question 3'!V$2,'Main Data'!$D$1:$AE$1,0)) -> 169.2 | W7: =INDEX('Main Data'!$D$1:$AE$373,MATCH('Question 3'!$S7,'Main Data'!$D$1:$D$373,0),MATCH('Question 3'!W$2,'Main Data'!$D$1:$AE$1,0)) -> 168.1 | X7: =INDEX('Main Data'!$D$1:$AE$373,MATCH('Question 3'!$S7,'Main Data'!$D$1:$D$373,0),MATCH('Question 3'!X$2,'Main Data'!$D$1:$AE$1,0)) -> 192.4 | Y7: =INDEX('Main Data'!$D$1:$AE$373,MATCH('Question 3'!$S7,'Main Data'!$D$1:$D$373,0),MATCH('Question 3'!Y$2,'Main Data'!$D$1:$AE$1,0)) -> 172.9 | Z7: =INDEX('Main Data'!$D$1:$AE$373,MATCH('Question 3'!$S7,'Main Data'!$D$1:$D$373,0),MATCH('Question 3'!Z$2,'Main Data'!$D$1:$AE$1,0)) -> 186.7 | AA7: =INDEX('Main Data'!$D$1:$AE$373,MATCH('Question 3'!$S7,'Main Data'!$D$1:$D$373,0),MATCH('Question 3'!AA$2,'Main Data'!$D$1:$AE$1,0)) -> 167.2 | ... AE7: =INDEX('Main Data'!$D$1:$AE$373,MATCH('Question 3'!$S7,'Main Data'!$D$1:$D$373,0),MATCH('Question 3'!AE$2,'Main Data'!$D$1:$AE$1,0)) -> 186.3 | AF7: =SUM(T7:AE7) -> 2092.9 | AH7: Oils and fats | AI7: =INDEX($S$2:$AE$16,MATCH(2022&"June"&"Rural+Urban",$S$2:$S$16,0),MATCH(AH7,$S$2:$AE$2,0)) -> 200.9 | AJ7: =INDEX($S$2:$AE$16,MATCH(2023&"May"&"Rural+Urban",$S$2:$S$16,0),MATCH(AH7,$S$2:$AE$2,0)) -> 170 | AK7: =(AJ7-AI7)/AI7*100 -> -15.380786
